Traceback (most recent call last):
  File "/Users/joelchan/opt/anaconda3/lib/python3.9/site-packages/jupyter_cache/executors/utils.py", line 51, in single_nb_execution
    executenb(
  File "/Users/joelchan/opt/anaconda3/lib/python3.9/site-packages/nbclient/client.py", line 1112, in execute
    return NotebookClient(nb=nb, resources=resources, km=km, **kwargs).execute()
  File "/Users/joelchan/opt/anaconda3/lib/python3.9/site-packages/nbclient/util.py", line 74, in wrapped
    return just_run(coro(*args, **kwargs))
  File "/Users/joelchan/opt/anaconda3/lib/python3.9/site-packages/nbclient/util.py", line 53, in just_run
    return loop.run_until_complete(coro)
  File "/Users/joelchan/opt/anaconda3/lib/python3.9/asyncio/base_events.py", line 642, in run_until_complete
    return future.result()
  File "/Users/joelchan/opt/anaconda3/lib/python3.9/site-packages/nbclient/client.py", line 553, in async_execute
    await self.async_execute_cell(
  File "/Users/joelchan/opt/anaconda3/lib/python3.9/site-packages/nbclient/client.py", line 857, in async_execute_cell
    self._check_raise_for_error(cell, exec_reply)
  File "/Users/joelchan/opt/anaconda3/lib/python3.9/site-packages/nbclient/client.py", line 760, in _check_raise_for_error
    raise CellExecutionError.from_cell_and_msg(cell, exec_reply_content)
nbclient.exceptions.CellExecutionError: An error occurred while executing the following cell:
------------------
# Step 2: apply the function
courses['area'] = courses['code'].apply(extract_area)
courses.head(10)
------------------

[0;31m---------------------------------------------------------------------------[0m
[0;31mKeyError[0m                                  Traceback (most recent call last)
[0;32m~/opt/anaconda3/lib/python3.9/site-packages/pandas/core/indexes/base.py[0m in [0;36mget_loc[0;34m(self, key, method, tolerance)[0m
[1;32m   3360[0m             [0;32mtry[0m[0;34m:[0m[0;34m[0m[0;34m[0m[0m
[0;32m-> 3361[0;31m                 [0;32mreturn[0m [0mself[0m[0;34m.[0m[0m_engine[0m[0;34m.[0m[0mget_loc[0m[0;34m([0m[0mcasted_key[0m[0;34m)[0m[0;34m[0m[0;34m[0m[0m
[0m[1;32m   3362[0m             [0;32mexcept[0m [0mKeyError[0m [0;32mas[0m [0merr[0m[0;34m:[0m[0;34m[0m[0;34m[0m[0m

[0;32m~/opt/anaconda3/lib/python3.9/site-packages/pandas/_libs/index.pyx[0m in [0;36mpandas._libs.index.IndexEngine.get_loc[0;34m()[0m

[0;32m~/opt/anaconda3/lib/python3.9/site-packages/pandas/_libs/index.pyx[0m in [0;36mpandas._libs.index.IndexEngine.get_loc[0;34m()[0m

[0;32mpandas/_libs/hashtable_class_helper.pxi[0m in [0;36mpandas._libs.hashtable.PyObjectHashTable.get_item[0;34m()[0m

[0;32mpandas/_libs/hashtable_class_helper.pxi[0m in [0;36mpandas._libs.hashtable.PyObjectHashTable.get_item[0;34m()[0m

[0;31mKeyError[0m: 'code'

The above exception was the direct cause of the following exception:

[0;31mKeyError[0m                                  Traceback (most recent call last)
[0;32m/var/folders/xz/_hjc5hsx743dclmg8n5678nc0000gn/T/ipykernel_89416/1864781452.py[0m in [0;36m<module>[0;34m[0m
[1;32m      1[0m [0;31m# Step 2: apply the function[0m[0;34m[0m[0;34m[0m[0m
[0;32m----> 2[0;31m [0mcourses[0m[0;34m[[0m[0;34m'area'[0m[0;34m][0m [0;34m=[0m [0mcourses[0m[0;34m[[0m[0;34m'code'[0m[0;34m][0m[0;34m.[0m[0mapply[0m[0;34m([0m[0mextract_area[0m[0;34m)[0m[0;34m[0m[0;34m[0m[0m
[0m[1;32m      3[0m [0mcourses[0m[0;34m.[0m[0mhead[0m[0;34m([0m[0;36m10[0m[0;34m)[0m[0;34m[0m[0;34m[0m[0m

[0;32m~/opt/anaconda3/lib/python3.9/site-packages/pandas/core/frame.py[0m in [0;36m__getitem__[0;34m(self, key)[0m
[1;32m   3456[0m             [0;32mif[0m [0mself[0m[0;34m.[0m[0mcolumns[0m[0;34m.[0m[0mnlevels[0m [0;34m>[0m [0;36m1[0m[0;34m:[0m[0;34m[0m[0;34m[0m[0m
[1;32m   3457[0m                 [0;32mreturn[0m [0mself[0m[0;34m.[0m[0m_getitem_multilevel[0m[0;34m([0m[0mkey[0m[0;34m)[0m[0;34m[0m[0;34m[0m[0m
[0;32m-> 3458[0;31m             [0mindexer[0m [0;34m=[0m [0mself[0m[0;34m.[0m[0mcolumns[0m[0;34m.[0m[0mget_loc[0m[0;34m([0m[0mkey[0m[0;34m)[0m[0;34m[0m[0;34m[0m[0m
[0m[1;32m   3459[0m             [0;32mif[0m [0mis_integer[0m[0;34m([0m[0mindexer[0m[0;34m)[0m[0;34m:[0m[0;34m[0m[0;34m[0m[0m
[1;32m   3460[0m                 [0mindexer[0m [0;34m=[0m [0;34m[[0m[0mindexer[0m[0;34m][0m[0;34m[0m[0;34m[0m[0m

[0;32m~/opt/anaconda3/lib/python3.9/site-packages/pandas/core/indexes/base.py[0m in [0;36mget_loc[0;34m(self, key, method, tolerance)[0m
[1;32m   3361[0m                 [0;32mreturn[0m [0mself[0m[0;34m.[0m[0m_engine[0m[0;34m.[0m[0mget_loc[0m[0;34m([0m[0mcasted_key[0m[0;34m)[0m[0;34m[0m[0;34m[0m[0m
[1;32m   3362[0m             [0;32mexcept[0m [0mKeyError[0m [0;32mas[0m [0merr[0m[0;34m:[0m[0;34m[0m[0;34m[0m[0m
[0;32m-> 3363[0;31m                 [0;32mraise[0m [0mKeyError[0m[0;34m([0m[0mkey[0m[0;34m)[0m [0;32mfrom[0m [0merr[0m[0;34m[0m[0;34m[0m[0m
[0m[1;32m   3364[0m [0;34m[0m[0m
[1;32m   3365[0m         [0;32mif[0m [0mis_scalar[0m[0;34m([0m[0mkey[0m[0;34m)[0m [0;32mand[0m [0misna[0m[0;34m([0m[0mkey[0m[0;34m)[0m [0;32mand[0m [0;32mnot[0m [0mself[0m[0;34m.[0m[0mhasnans[0m[0;34m:[0m[0;34m[0m[0;34m[0m[0m

[0;31mKeyError[0m: 'code'
KeyError: 'code'

