Traceback (most recent call last):
  File "/Users/joelchan/opt/anaconda3/lib/python3.9/site-packages/jupyter_cache/executors/utils.py", line 51, in single_nb_execution
    executenb(
  File "/Users/joelchan/opt/anaconda3/lib/python3.9/site-packages/nbclient/client.py", line 1112, in execute
    return NotebookClient(nb=nb, resources=resources, km=km, **kwargs).execute()
  File "/Users/joelchan/opt/anaconda3/lib/python3.9/site-packages/nbclient/util.py", line 74, in wrapped
    return just_run(coro(*args, **kwargs))
  File "/Users/joelchan/opt/anaconda3/lib/python3.9/site-packages/nbclient/util.py", line 53, in just_run
    return loop.run_until_complete(coro)
  File "/Users/joelchan/opt/anaconda3/lib/python3.9/asyncio/base_events.py", line 642, in run_until_complete
    return future.result()
  File "/Users/joelchan/opt/anaconda3/lib/python3.9/site-packages/nbclient/client.py", line 553, in async_execute
    await self.async_execute_cell(
  File "/Users/joelchan/opt/anaconda3/lib/python3.9/site-packages/nbclient/client.py", line 857, in async_execute_cell
    self._check_raise_for_error(cell, exec_reply)
  File "/Users/joelchan/opt/anaconda3/lib/python3.9/site-packages/nbclient/client.py", line 760, in _check_raise_for_error
    raise CellExecutionError.from_cell_and_msg(cell, exec_reply_content)
nbclient.exceptions.CellExecutionError: An error occurred while executing the following cell:
------------------
def stir():
    print("stirring")

def check_sauce():
    print("Checking sauce")
    
stir()
if check_sauce() == "thick":
    stir()
    if check_sauce() == "thick":
------------------

[0;36m  File [0;32m"/var/folders/xz/_hjc5hsx743dclmg8n5678nc0000gn/T/ipykernel_10224/4217383764.py"[0;36m, line [0;32m10[0m
[0;31m    if check_sauce() == "thick":[0m
[0m                                ^[0m
[0;31mIndentationError[0m[0;31m:[0m expected an indented block

IndentationError: expected an indented block (4217383764.py, line 10)

